Traceback (most recent call last):
  File "/home/users/mhturner/SC-FC/get_region_responses.py", line 27, in <module>
    roi_mask, _ = RegionConnectivity.loadAtlasData(atlas_fp, roinames_path, mapping=mapping)
  File "/home/users/mhturner/SC-FC/region_connectivity/RegionConnectivity.py", line 56, in loadAtlasData
    roi_names = pd.read_csv(roinames_path, sep=',', header=0).name.to_numpy()
  File "/home/users/mhturner/.local/lib/python3.6/site-packages/pandas/io/parsers.py", line 702, in parser_f
    return _read(filepath_or_buffer, kwds)
  File "/home/users/mhturner/.local/lib/python3.6/site-packages/pandas/io/parsers.py", line 429, in _read
    parser = TextFileReader(filepath_or_buffer, **kwds)
  File "/home/users/mhturner/.local/lib/python3.6/site-packages/pandas/io/parsers.py", line 895, in __init__
    self._make_engine(self.engine)
  File "/home/users/mhturner/.local/lib/python3.6/site-packages/pandas/io/parsers.py", line 1122, in _make_engine
    self._engine = CParserWrapper(self.f, **self.options)
  File "/home/users/mhturner/.local/lib/python3.6/site-packages/pandas/io/parsers.py", line 1853, in __init__
    self._reader = parsers.TextReader(src, **kwds)
  File "pandas/_libs/parsers.pyx", line 387, in pandas._libs.parsers.TextReader.__cinit__
  File "pandas/_libs/parsers.pyx", line 705, in pandas._libs.parsers.TextReader._setup_parser_source
FileNotFoundError: [Errno 2] File b'/oak/stanford/groups/trc/data/Max/flynet/data/Original_Index_panda_full.csv' does not exist: b'/oak/stanford/groups/trc/data/Max/flynet/data/Original_Index_panda_full.csv'
