Traceback (most recent call last):
  File "/home/users/mhturner/.local/lib/python3.6/site-packages/nibabel/loadsave.py", line 40, in load
    stat_result = os.stat(filename)
FileNotFoundError: [Errno 2] No such file or directory: '/oak/stanford/groups/trc/data/Max/flynet/data/vfb_68_2017-10-30_2.nii.gz'

During handling of the above exception, another exception occurred:

Traceback (most recent call last):
  File "/home/users/mhturner/SC-FC/get_region_responses.py", line 27, in <module>
    roi_mask, _ = RegionConnectivity.loadAtlasData(atlas_fp, roinames_path, mapping=mapping)
  File "/home/users/mhturner/SC-FC/region_connectivity/RegionConnectivity.py", line 57, in loadAtlasData
    mask_brain = np.asarray(np.squeeze(nib.load(atlas_path).get_fdata()), 'uint8')
  File "/home/users/mhturner/.local/lib/python3.6/site-packages/nibabel/loadsave.py", line 42, in load
    raise FileNotFoundError("No such file or no access: '%s'" % filename)
FileNotFoundError: No such file or no access: '/oak/stanford/groups/trc/data/Max/flynet/data/vfb_68_2017-10-30_2.nii.gz'
